Workbook

Sheet Dashboard
A1: FORMIVA PROJECT MANAGEMENT DASHBOARD
A2: Daily operating view | Update Task Tracker and Daily Status; dashboard formulas update automatically | v2.1 (PRD phase numbers, rebased calendar)
A4: Total Tasks | C4: Completed | E4: Blocked | G4: Avg Progress
A5: =COUNTA('Task Tracker'!A2:A200) -> 90 | C5: =COUNTIF('Task Tracker'!H2:H200,"Done") -> 0 | E5: =COUNTIF('Task Tracker'!H2:H200,"Blocked") -> 0 | G5: =IFERROR(AVERAGE('Task Tracker'!K2:K200),0) -> 0
A8: STATUS SUMMARY | D8: PHASE SUMMARY
A9: Not Started | B9: =COUNTIF('Task Tracker'!H2:H200,A9) -> 84 | D9: Phase 0 Discovery | E9: =COUNTIF('Task Tracker'!B2:B200,0) -> 9 | F9: =IFERROR(AVERAGEIF('Task Tracker'!B2:B200,0,'Task Tracker'!K2:K200),0) -> 0
A10: In Progress | B10: =COUNTIF('Task Tracker'!H2:H200,A10) -> 0 | D10: Phase 1 Foundations | E10: =COUNTIF('Task Tracker'!B2:B200,1) -> 19 | F10: =IFERROR(AVERAGEIF('Task Tracker'!B2:B200,1,'Task Tracker'!K2:K200),0) -> 0
A11: Blocked | B11: =COUNTIF('Task Tracker'!H2:H200,A11) -> 0 | D11: Phase 2 Database | E11: =COUNTIF('Task Tracker'!B2:B200,2) -> 7 | F11: =IFERROR(AVERAGEIF('Task Tracker'!B2:B200,2,'Task Tracker'!K2:K200),0) -> 0
A12: Done | B12: =COUNTIF('Task Tracker'!H2:H200,A12) -> 0 | D12: Phase 3 Intake | E12: =COUNTIF('Task Tracker'!B2:B200,3) -> 7 | F12: =IFERROR(AVERAGEIF('Task Tracker'!B2:B200,3,'Task Tracker'!K2:K200),0) -> 0
A13: On Hold | B13: =COUNTIF('Task Tracker'!H2:H200,A13) -> 6 | D13: Phase 4 Review | E13: =COUNTIF('Task Tracker'!B2:B200,4) -> 4 | F13: =IFERROR(AVERAGEIF('Task Tracker'!B2:B200,4,'Task Tracker'!K2:K200),0) -> 0
A14: Overdue or blocked (RED) | B14: =COUNTIF('Task Tracker'!P2:P200,"RED") -> 0 | D14: Phase 5 Workers | E14: =COUNTIF('Task Tracker'!B2:B200,5) -> 5 | F14: =IFERROR(AVERAGEIF('Task Tracker'!B2:B200,5,'Task Tracker'!K2:K200),0) -> 0
A15: Due within 7 days (AMBER) | B15: =COUNTIF('Task Tracker'!P2:P200,"AMBER") -> 9 | D15: Phase 6 AI Engine | E15: =COUNTIF('Task Tracker'!B2:B200,6) -> 7 | F15: =IFERROR(AVERAGEIF('Task Tracker'!B2:B200,6,'Task Tracker'!K2:K200),0) -> 0
D16: Phase 7 Routing + E2E | E16: =COUNTIF('Task Tracker'!B2:B200,7) -> 6 | F16: =IFERROR(AVERAGEIF('Task Tracker'!B2:B200,7,'Task Tracker'!K2:K200),0) -> 0
D17: Phase 8 Editor (gated) | E17: =COUNTIF('Task Tracker'!B2:B200,8) -> 2 | F17: =IFERROR(AVERAGEIF('Task Tracker'!B2:B200,8,'Task Tracker'!K2:K200),0) -> 0
D18: Phase 9 Integrations | E18: =COUNTIF('Task Tracker'!B2:B200,9) -> 4 | F18: =IFERROR(AVERAGEIF('Task Tracker'!B2:B200,9,'Task Tracker'!K2:K200),0) -> 0
D19: Phase 10 Hardening | E19: =COUNTIF('Task Tracker'!B2:B200,10) -> 16 | F19: =IFERROR(AVERAGEIF('Task Tracker'!B2:B200,10,'Task Tracker'!K2:K200),0) -> 0
D20: Phase 11 Measure | E20: =COUNTIF('Task Tracker'!B2:B200,11) -> 4 | F20: =IFERROR(AVERAGEIF('Task Tracker'!B2:B200,11,'Task Tracker'!K2:K200),0) -> 0
A22: NEXT GATE
A23: Next gate date | B23: =IFERROR(SMALL(Milestones!B2:B13,COUNTIF(Milestones!B2:B13,"<"&TODAY())+1),"None") -> 46298 | C23: Next gate | D23: =IFERROR(INDEX(Milestones!A2:A13,MATCH(B23,Milestones!B2:B13,0)),"All dates passed") -> Discovery gate
A25: TODAY / DAILY STATUS
A26: Today | B26: =TODAY() -> 46285 | C26: Current daily status | D26: =IFERROR(INDEX('Daily Status'!C:C,MATCH(TODAY(),'Daily Status'!A:A,0)),"Not in range") -> Not in range
A27: Today focus | B27: =IFERROR(INDEX('Daily Status'!E:E,MATCH(TODAY(),'Daily Status'!A:A,0)),"Log runs 21 Sep 2026 to 1 Jan 2027") -> Log runs 21 Sep 2026 to 1 Jan 2027
A29: NEXT ACTIONS
A30: Use the Task Tracker filters to identify overdue, blocked and high-priority work. Update % Complete as a decimal (e.g., 50% or 0.5). Phase 8 and 9 tasks are On Hold until three paid pilots or a pilot request (ADR-05). Rebuilt for v2.1 on 20 September 2026: dates start Monday 21 September 2026.

Sheet Lists
A1: Task Status | B1: Priority | C1: Area | D1: Owner | E1: Daily Status
A2: Not Started | B2: Critical | C2: Product | D2: Founder
A3: In Progress | B3: High | C3: AI Engine | D3: AI Assistant
A4: Blocked | B4: Medium | C4: Backend | D4: Developer
A5: Done | B5: Low | C5: Database | D5: Designer
A6: On Hold | C6: Frontend | D6: Advisor
C7: Workflow Builder | D7: External Provider
C8: Integrations | D8: Technical Reviewer
C9: Infrastructure | D9: Counsel
C10: Security
C11: GTM
C12: Founder Learning

Sheet Task Tracker
A1: ID | B1: Phase | C1: Area | D1: Task | E1: Description / Definition of Done | F1: Owner | G1: Priority | H1: Status | I1: Start Date | J1: Due Date | K1: % Complete | L1: Dependencies | M1: Next Action | N1: Notes | O1: Days Left | P1: Health
A2: F-001 | B2: 0 | C2: GTM | D2: Interview 15-20 target firms | E2: Same fields for every interview: recurring onboarding pain, tools, rework, time, willingness to pay. Wedge validated if 8 of 15 name the same rework problem. | F2: Founder | G2: Critical | H2: Not Started | I2: 46286 | J2: 46298 | K2: 0 | M2: Build list of 40 target firms | N2: Business Plan gate; Coding Plan Phase 0 | O2: =IF(H2="Done",0,IF(J2<TODAY(),"OVERDUE",J2-TODAY())) -> 13 | P2: =IF(H2="Blocked","RED",IF(H2="Done","GREEN",IF(J2<TODAY(),"RED",IF(J2-TODAY()<=7,"AMBER","GREEN")))) -> GREEN
A3: F-002 | B3: 0 | C3: GTM | D3: Recruit 3 committed design partners | E3: Three firms willing to pilot employee onboarding (letter of intent or paid pilot commitment). | F3: Founder | G3: Critical | H3: Not Started | I3: 46286 | J3: 46298 | K3: 0 | L3: F-001 | M3: Ask at the end of every interview | N3: Discovery gate | O3: =IF(H3="Done",0,IF(J3<TODAY(),"OVERDUE",J3-TODAY())) -> 13 | P3: =IF(H3="Blocked","RED",IF(H3="Done","GREEN",IF(J3<TODAY(),"RED",IF(J3-TODAY()<=7,"AMBER","GREEN")))) -> GREEN
A4: F-003 | B4: 0 | C4: GTM | D4: Baseline worksheet and 20-minute diagnostic script | E4: Reusable worksheet measuring current onboarding time, rework and handoffs; script from Sales Strategy stage 1. | F4: Founder | G4: High | H4: Not Started | I4: 46286 | J4: 46290 | K4: 0 | M4: Draft script | N4: Use identical fields per interview | O4: =IF(H4="Done",0,IF(J4<TODAY(),"OVERDUE",J4-TODAY())) -> 5 | P4: =IF(H4="Blocked","RED",IF(H4="Done","GREEN",IF(J4<TODAY(),"RED",IF(J4-TODAY()<=7,"AMBER","GREEN")))) -> AMBER
A5: F-004 | B5: 0 | C5: Product | D5: Create private repository and decision log; record ADR-01 to ADR-12 | E5: DECISIONS.md, ASSUMPTIONS.md, SECURITY.md committed; each ADR accepted or changed with a reason. | F5: Founder | G5: High | H5: Not Started | I5: 46286 | J5: 46288 | K5: 0 | M5: Create repository | N5: Review document section 5 | O5: =IF(H5="Done",0,IF(J5<TODAY(),"OVERDUE",J5-TODAY())) -> 3 | P5: =IF(H5="Blocked","RED",IF(H5="Done","GREEN",IF(J5<TODAY(),"RED",IF(J5-TODAY()<=7,"AMBER","GREEN")))) -> AMBER
A6: F-005 | B6: 0 | C6: AI Engine | D6: Generate and validate the 100-case synthetic corpus | E6: Coding Plan Prompt 0.1. Watermarked, no valid ID numbers, 10 hostile files, deterministic seed, coverage report. | F6: AI Assistant | G6: Critical | H6: Not Started | I6: 46293 | J6: 46297 | K6: 0 | M6: Paste master context block then Prompt 0.1 | N6: Never real documents | O6: =IF(H6="Done",0,IF(J6<TODAY(),"OVERDUE",J6-TODAY())) -> 12 | P6: =IF(H6="Blocked","RED",IF(H6="Done","GREEN",IF(J6<TODAY(),"RED",IF(J6-TODAY()<=7,"AMBER","GREEN")))) -> GREEN
A7: F-006 | B7: 0 | C7: Product | D7: Agree routing matrix and document classes | E7: Nine POC scenarios plus classes identity, address, education, employment, bank, tax, photo, other. | F7: Founder | G7: High | H7: Not Started | I7: 46293 | J7: 46295 | K7: 0 | M7: Review POC routing matrix | N7: Signed decision record | O7: =IF(H7="Done",0,IF(J7<TODAY(),"OVERDUE",J7-TODAY())) -> 10 | P7: =IF(H7="Blocked","RED",IF(H7="Done","GREEN",IF(J7<TODAY(),"RED",IF(J7-TODAY()<=7,"AMBER","GREEN")))) -> GREEN
A8: F-007 | B8: 0 | C8: AI Engine | D8: Pre-register benchmark thresholds | E8: Coding Plan Prompt 0.2. Thresholds committed BEFORE any benchmark run; CI blocks later edits. | F8: Founder | G8: Critical | H8: Not Started | I8: 46296 | J8: 46297 | K8: 0 | L8: F-005 | M8: Fill preregistration.yaml | N8: Prevents moving the goalposts | O8: =IF(H8="Done",0,IF(J8<TODAY(),"OVERDUE",J8-TODAY())) -> 12 | P8: =IF(H8="Blocked","RED",IF(H8="Done","GREEN",IF(J8<TODAY(),"RED",IF(J8-TODAY()<=7,"AMBER","GREEN")))) -> GREEN
A9: F-008 | B9: 0 | C9: GTM | D9: Discovery gate decision | E9: At least 8 of 15 interviews name the same problem and 3 firms will pilot. If not, change ICP, offer or price before Phase 2. | F9: Founder | G9: Critical | H9: Not Started | I9: 46298 | J9: 46298 | K9: 0 | L9: F-001,F-002 | M9: Hold gate review | N9: Milestone: Discovery gate | O9: =IF(H9="Done",0,IF(J9<TODAY(),"OVERDUE",J9-TODAY())) -> 13 | P9: =IF(H9="Blocked","RED",IF(H9="Done","GREEN",IF(J9<TODAY(),"RED",IF(J9-TODAY()<=7,"AMBER","GREEN")))) -> GREEN
A10: F-009 | B10: 0 | C10: Security | D10: Engage a freelance technical reviewer | E10: Reviewer agreed for Phases 2, 5, 6, 7 and 10 pull requests (a few hours per phase). | F10: Founder | G10: High | H10: Not Started | I10: 46286 | J10: 46297 | K10: 0 | M10: Shortlist 2-3 reviewers | N10: Budget line needed | O10: =IF(H10="Done",0,IF(J10<TODAY(),"OVERDUE",J10-TODAY())) -> 12 | P10: =IF(H10="Blocked","RED",IF(H10="Done","GREEN",IF(J10<TODAY(),"RED",IF(J10-TODAY()<=7,"AMBER","GREEN")))) -> GREEN
A11: F-010 | B11: 1 | C11: Infrastructure | D11: Check OCI status of Server #1 | E11: Is instance-20260530-1135 running? Shape, account type (Always Free or Pay-As-You-Go), Oracle emails since June 2026. | F11: Founder | G11: Critical | H11: Not Started | I11: 46286 | J11: 46286 | K11: 0 | M11: Open OCI console | N11: Review document finding F-01 | O11: =IF(H11="Done",0,IF(J11<TODAY(),"OVERDUE",J11-TODAY())) -> 1 | P11: =IF(H11="Blocked","RED",IF(H11="Done","GREEN",IF(J11<TODAY(),"RED",IF(J11-TODAY()<=7,"AMBER","GREEN")))) -> AMBER
A12: F-011 | B12: 1 | C12: Infrastructure | D12: Upgrade OCI to Pay-As-You-Go with budget alert | E12: Account upgraded; budget alert set (for example INR 6,000 per month). | F12: Founder | G12: Critical | H12: Not Started | I12: 46286 | J12: 46287 | K12: 0 | L12: F-010 | M12: Upgrade account | N12: ADR-08 | O12: =IF(H12="Done",0,IF(J12<TODAY(),"OVERDUE",J12-TODAY())) -> 2 | P12: =IF(H12="Blocked","RED",IF(H12="Done","GREEN",IF(J12<TODAY(),"RED",IF(J12-TODAY()<=7,"AMBER","GREEN")))) -> AMBER
A13: F-012 | B13: 1 | C13: Infrastructure | D13: Right-size VM1 and create VM2 | E13: VM1 2 OCPU / 12 GB; VM2 4 OCPU / 16 GB (Ampere A1, India South). Retry other availability domains if capacity is short. | F13: Founder | G13: Critical | H13: Not Started | I13: 46287 | J13: 46290 | K13: 0 | L13: F-011 | M13: Resize VM1; create VM2 | N13: ADR-01 | O13: =IF(H13="Done",0,IF(J13<TODAY(),"OVERDUE",J13-TODAY())) -> 5 | P13: =IF(H13="Blocked","RED",IF(H13="Done","GREEN",IF(J13<TODAY(),"RED",IF(J13-TODAY()<=7,"AMBER","GREEN")))) -> AMBER
A14: F-013 | B14: 1 | C14: Security | D14: Harden Server #1 | E14: Key-only SSH, PasswordAuthentication no, PermitRootLogin no, replace NOPASSWD:ALL, no public port 22, automatic security updates. | F14: Founder | G14: Critical | H14: Not Started | I14: 46286 | J14: 46289 | K14: 0 | M14: Add key, test second session, then disable passwords | N14: Do BEFORE any data. Runbook host-hardening.md | O14: =IF(H14="Done",0,IF(J14<TODAY(),"OVERDUE",J14-TODAY())) -> 4 | P14: =IF(H14="Blocked","RED",IF(H14="Done","GREEN",IF(J14<TODAY(),"RED",IF(J14-TODAY()<=7,"AMBER","GREEN")))) -> AMBER
A15: F-014 | B15: 1 | C15: Infrastructure | D15: Configure VCN and network security groups | E15: VM2 private subnet, no public IP; VM1 no inbound rules; only VM1 to VM2 port 8080. | F15: Founder | G15: Critical | H15: Not Started | I15: 46288 | J15: 46290 | K15: 0 | L15: F-012 | M15: Create NSGs | N15: ADR-03 | O15: =IF(H15="Done",0,IF(J15<TODAY(),"OVERDUE",J15-TODAY())) -> 5 | P15: =IF(H15="Blocked","RED",IF(H15="Done","GREEN",IF(J15<TODAY(),"RED",IF(J15-TODAY()<=7,"AMBER","GREEN")))) -> AMBER
A16: F-015 | B16: 1 | C16: Infrastructure | D16: Docker, Compose and resource limits on both VMs | E16: Docker running; log rotation; container memory and CPU limits. | F16: Founder | G16: High | H16: Not Started | I16: 46289 | J16: 46293 | K16: 0 | L16: F-012 | M16: Install Docker | N16: Prompt 1.2 output | O16: =IF(H16="Done",0,IF(J16<TODAY(),"OVERDUE",J16-TODAY())) -> 8 | P16: =IF(H16="Blocked","RED",IF(H16="Done","GREEN",IF(J16<TODAY(),"RED",IF(J16-TODAY()<=7,"AMBER","GREEN")))) -> GREEN
A17: F-016 | B17: 1 | C17: Infrastructure | D17: Cloudflare Tunnel, Access and WAF | E17: Tunnel to VM1 port 8000 (api.vishyxtechie.in); Access policy for admin routes; rate limits on the public form path. | F17: Founder | G17: High | H17: Not Started | I17: 46290 | J17: 46294 | K17: 0 | L17: F-013 | M17: Point tunnel at port 8000 | N17: Existing tunnel reused | O17: =IF(H17="Done",0,IF(J17<TODAY(),"OVERDUE",J17-TODAY())) -> 9 | P17: =IF(H17="Blocked","RED",IF(H17="Done","GREEN",IF(J17<TODAY(),"RED",IF(J17-TODAY()<=7,"AMBER","GREEN")))) -> GREEN
A18: F-017 | B18: 1 | C18: Infrastructure | D18: Vercel Pro team and project | E18: Pro plan (commercial use), Preview and Production separated, no production secrets in Preview. | F18: Founder | G18: High | H18: Not Started | I18: 46290 | J18: 46294 | K18: 0 | M18: Create team | N18: ADR-08 | O18: =IF(H18="Done",0,IF(J18<TODAY(),"OVERDUE",J18-TODAY())) -> 9 | P18: =IF(H18="Blocked","RED",IF(H18="Done","GREEN",IF(J18<TODAY(),"RED",IF(J18-TODAY()<=7,"AMBER","GREEN")))) -> GREEN
A19: F-018 | B19: 1 | C19: Security | D19: Clerk development and production instances | E19: Sign-in configured, MFA for owners and admins, webhook endpoint with signing secret. | F19: Founder | G19: High | H19: Not Started | I19: 46293 | J19: 46296 | K19: 0 | M19: Create instances | N19: Authentication only | O19: =IF(H19="Done",0,IF(J19<TODAY(),"OVERDUE",J19-TODAY())) -> 11 | P19: =IF(H19="Blocked","RED",IF(H19="Done","GREEN",IF(J19<TODAY(),"RED",IF(J19-TODAY()<=7,"AMBER","GREEN")))) -> GREEN
A20: F-019 | B20: 1 | C20: Infrastructure | D20: R2 buckets and scoped tokens | E20: formiva-quarantine, formiva-docs, formiva-backups; no public access; least-privilege token per bucket; lifecycle rules. | F20: Founder | G20: High | H20: Not Started | I20: 46293 | J20: 46296 | K20: 0 | M20: Create buckets | N20: Decision D-2 (data location) open | O20: =IF(H20="Done",0,IF(J20<TODAY(),"OVERDUE",J20-TODAY())) -> 11 | P20: =IF(H20="Blocked","RED",IF(H20="Done","GREEN",IF(J20<TODAY(),"RED",IF(J20-TODAY()<=7,"AMBER","GREEN")))) -> GREEN
A21: F-020 | B21: 1 | C21: Integrations | D21: Resend sending domain verified | E21: SPF, DKIM and DMARC records in place; test email delivered. | F21: Founder | G21: Medium | H21: Not Started | I21: 46293 | J21: 46297 | K21: 0 | M21: Add domain | N21: Free-tier limits: verify | O21: =IF(H21="Done",0,IF(J21<TODAY(),"OVERDUE",J21-TODAY())) -> 12 | P21: =IF(H21="Blocked","RED",IF(H21="Done","GREEN",IF(J21<TODAY(),"RED",IF(J21-TODAY()<=7,"AMBER","GREEN")))) -> GREEN
A22: F-021 | B22: 1 | C22: Security | D22: GitHub protections and scanning | E22: Branch protection on main, required checks, secret scanning, Dependabot. | F22: Founder | G22: High | H22: Not Started | I22: 46286 | J22: 46290 | K22: 0 | L22: F-004 | M22: Enable protections | N22: MFA on all accounts | O22: =IF(H22="Done",0,IF(J22<TODAY(),"OVERDUE",J22-TODAY())) -> 5 | P22: =IF(H22="Blocked","RED",IF(H22="Done","GREEN",IF(J22<TODAY(),"RED",IF(J22-TODAY()<=7,"AMBER","GREEN")))) -> AMBER
A23: F-022 | B23: 1 | C23: Security | D23: Choose secrets approach and create inventory | E23: SOPS with age or OCI Vault (decision D-4); secret inventory sheet with owners and rotation dates. | F23: Founder | G23: High | H23: Not Started | I23: 46293 | J23: 46297 | K23: 0 | M23: Decide D-4 | N23: Master-key custody plan | O23: =IF(H23="Done",0,IF(J23<TODAY(),"OVERDUE",J23-TODAY())) -> 12 | P23: =IF(H23="Blocked","RED",IF(H23="Done","GREEN",IF(J23<TODAY(),"RED",IF(J23-TODAY()<=7,"AMBER","GREEN")))) -> GREEN
A24: F-023 | B24: 1 | C24: Infrastructure | D24: Uptime and heartbeat monitoring | E24: Service pinging /healthz with alert email (decision D-3); one test alert received. | F24: Founder | G24: Medium | H24: Not Started | I24: 46294 | J24: 46297 | K24: 0 | L24: F-016 | M24: Pick service | N24: Verify free-tier limits | O24: =IF(H24="Done",0,IF(J24<TODAY(),"OVERDUE",J24-TODAY())) -> 12 | P24: =IF(H24="Blocked","RED",IF(H24="Done","GREEN",IF(J24<TODAY(),"RED",IF(J24-TODAY()<=7,"AMBER","GREEN")))) -> GREEN
A25: F-024 | B25: 1 | C25: Backend | D25: Monorepo scaffold and config validation | E25: Coding Plan Prompt 1.1. make verify passes on a clean clone; config loader never echoes secrets. | F25: AI Assistant | G25: High | H25: Not Started | I25: 46289 | J25: 46293 | K25: 0 | L25: F-004 | M25: Run Prompt 1.1 | N25: Master context block first | O25: =IF(H25="Done",0,IF(J25<TODAY(),"OVERDUE",J25-TODAY())) -> 8 | P25: =IF(H25="Blocked","RED",IF(H25="Done","GREEN",IF(J25<TODAY(),"RED",IF(J25-TODAY()<=7,"AMBER","GREEN")))) -> GREEN
A26: F-025 | B26: 1 | C26: Infrastructure | D26: Compose files for VM1 and VM2 | E26: Coding Plan Prompt 1.2. No database or AI port published on 0.0.0.0. | F26: AI Assistant | G26: High | H26: Not Started | I26: 46290 | J26: 46294 | K26: 0 | L26: F-024 | M26: Run Prompt 1.2 | N26: arm64 | O26: =IF(H26="Done",0,IF(J26<TODAY(),"OVERDUE",J26-TODAY())) -> 9 | P26: =IF(H26="Blocked","RED",IF(H26="Done","GREEN",IF(J26<TODAY(),"RED",IF(J26-TODAY()<=7,"AMBER","GREEN")))) -> GREEN
A27: F-026 | B27: 1 | C27: Security | D27: Host hardening script | E27: Coding Plan Prompt 1.3. Idempotent, dry-run, refuses to lock out the operator. | F27: AI Assistant | G27: High | H27: Not Started | I27: 46287 | J27: 46289 | K27: 0 | M27: Run Prompt 1.3 | N27: Use for VM2 too | O27: =IF(H27="Done",0,IF(J27<TODAY(),"OVERDUE",J27-TODAY())) -> 4 | P27: =IF(H27="Blocked","RED",IF(H27="Done","GREEN",IF(J27<TODAY(),"RED",IF(J27-TODAY()<=7,"AMBER","GREEN")))) -> AMBER
A28: F-027 | B28: 1 | C28: Security | D28: CI pipeline | E28: Coding Plan Prompt 1.4. Lint, tests, DB tests, secret scan, audits, semgrep, Trivy; fake secret must fail the build. | F28: AI Assistant | G28: High | H28: Not Started | I28: 46293 | J28: 46296 | K28: 0 | L28: F-024 | M28: Run Prompt 1.4 | N28: Stable required-check names | O28: =IF(H28="Done",0,IF(J28<TODAY(),"OVERDUE",J28-TODAY())) -> 11 | P28: =IF(H28="Blocked","RED",IF(H28="Done","GREEN",IF(J28<TODAY(),"RED",IF(J28-TODAY()<=7,"AMBER","GREEN")))) -> GREEN
A29: F-028 | B29: 1 | C29: Infrastructure | D29: Phase 1 exit test and decision record | E29: External port scan shows only Cloudflare-fronted HTTPS; health checks pass; no third VM or extra provider. | F29: Founder | G29: Critical | H29: Not Started | I29: 46297 | J29: 46297 | K29: 0 | L29: F-013,F-014,F-016,F-025 | M29: Run scan from outside | N29: Appendix A record | O29: =IF(H29="Done",0,IF(J29<TODAY(),"OVERDUE",J29-TODAY())) -> 12 | P29: =IF(H29="Blocked","RED",IF(H29="Done","GREEN",IF(J29<TODAY(),"RED",IF(J29-TODAY()<=7,"AMBER","GREEN")))) -> GREEN
A30: F-029 | B30: 2 | C30: Database | D30: Apply migrations and run the 81 SQL checks | E30: Delivered Formiva_DB_v2.1 applied locally and in CI; all checks pass. | F30: AI Assistant | G30: Critical | H30: Not Started | I30: 46300 | J30: 46300 | K30: 0 | L30: F-028 | M30: Copy migrations into packages/db | N30: Coding Plan Phase 2 | O30: =IF(H30="Done",0,IF(J30<TODAY(),"OVERDUE",J30-TODAY())) -> 15 | P30: =IF(H30="Blocked","RED",IF(H30="Done","GREEN",IF(J30<TODAY(),"RED",IF(J30-TODAY()<=7,"AMBER","GREEN")))) -> GREEN
A31: F-030 | B31: 2 | C31: Database | D31: Create runtime roles and apply migrations on VM1 | E31: LOGIN roles inheriting the four group roles; app role has no BYPASSRLS. | F31: Founder | G31: Critical | H31: Not Started | I31: 46301 | J31: 46301 | K31: 0 | L31: F-029 | M31: Create roles | N31: Passwords from the secret store | O31: =IF(H31="Done",0,IF(J31<TODAY(),"OVERDUE",J31-TODAY())) -> 16 | P31: =IF(H31="Blocked","RED",IF(H31="Done","GREEN",IF(J31<TODAY(),"RED",IF(J31-TODAY()<=7,"AMBER","GREEN")))) -> GREEN
A32: F-031 | B32: 2 | C32: Database | D32: Database package: runner, withTenant, Drizzle types | E32: Coding Plan Prompt 2.1. Checksummed migrations; no raw SQL outside packages/db. | F32: AI Assistant | G32: Critical | H32: Not Started | I32: 46300 | J32: 46301 | K32: 0 | L32: F-029 | M32: Run Prompt 2.1 | N32: Reviewer required | O32: =IF(H32="Done",0,IF(J32<TODAY(),"OVERDUE",J32-TODAY())) -> 16 | P32: =IF(H32="Blocked","RED",IF(H32="Done","GREEN",IF(J32<TODAY(),"RED",IF(J32-TODAY()<=7,"AMBER","GREEN")))) -> GREEN
A33: F-032 | B33: 2 | C33: Backend | D33: Auth plugin: Clerk JWT, workspace selector, permissions | E33: Coding Plan Prompt 2.2. Fails closed; header is only a selector. | F33: AI Assistant | G33: Critical | H33: Not Started | I33: 46301 | J33: 46303 | K33: 0 | L33: F-031 | M33: Run Prompt 2.2 | N33: Reviewer required | O33: =IF(H33="Done",0,IF(J33<TODAY(),"OVERDUE",J33-TODAY())) -> 18 | P33: =IF(H33="Blocked","RED",IF(H33="Done","GREEN",IF(J33<TODAY(),"RED",IF(J33-TODAY()<=7,"AMBER","GREEN")))) -> GREEN
A34: F-033 | B34: 2 | C34: Backend | D34: Workspace bootstrap and members API | E34: Coding Plan Prompt 2.3. Last owner protected; every change audited; OpenAPI drift check. | F34: AI Assistant | G34: High | H34: Not Started | I34: 46302 | J34: 46303 | K34: 0 | L34: F-032 | M34: Run Prompt 2.3 | O34: =IF(H34="Done",0,IF(J34<TODAY(),"OVERDUE",J34-TODAY())) -> 18 | P34: =IF(H34="Blocked","RED",IF(H34="Done","GREEN",IF(J34<TODAY(),"RED",IF(J34-TODAY()<=7,"AMBER","GREEN")))) -> GREEN
A35: F-034 | B35: 2 | C35: Security | D35: Tenant isolation negative suite from OpenAPI | E35: Coding Plan Prompt 2.4. Every route tested with foreign IDs, no auth and low role; new routes covered automatically. | F35: AI Assistant | G35: Critical | H35: Not Started | I35: 46303 | J35: 46304 | K35: 0 | L35: F-033 | M35: Run Prompt 2.4 | N35: Gate: tenant isolation | O35: =IF(H35="Done",0,IF(J35<TODAY(),"OVERDUE",J35-TODAY())) -> 19 | P35: =IF(H35="Blocked","RED",IF(H35="Done","GREEN",IF(J35<TODAY(),"RED",IF(J35-TODAY()<=7,"AMBER","GREEN")))) -> GREEN
A36: F-035 | B36: 2 | C36: Security | D36: Technical review and Phase 2 gate | E36: Reviewer signs the Phase 2 pull requests and decision record. | F36: Technical Reviewer | G36: Critical | H36: Not Started | I36: 46304 | J36: 46304 | K36: 0 | L36: F-034 | M36: Send PR list | N36: Milestone: Tenant isolation gate | O36: =IF(H36="Done",0,IF(J36<TODAY(),"OVERDUE",J36-TODAY())) -> 19 | P36: =IF(H36="Blocked","RED",IF(H36="Done","GREEN",IF(J36<TODAY(),"RED",IF(J36-TODAY()<=7,"AMBER","GREEN")))) -> GREEN
A37: F-036 | B37: 3 | C37: Frontend | D37: Form definition, publish flow and public renderer | E37: Coding Plan Prompt 3.1. Mobile first; axe accessibility clean; published versions immutable. | F37: AI Assistant | G37: High | H37: Not Started | I37: 46307 | J37: 46308 | K37: 0 | L37: F-035 | M37: Run Prompt 3.1 | N37: No ID-number fields | O37: =IF(H37="Done",0,IF(J37<TODAY(),"OVERDUE",J37-TODAY())) -> 23 | P37: =IF(H37="Blocked","RED",IF(H37="Done","GREEN",IF(J37<TODAY(),"RED",IF(J37-TODAY()<=7,"AMBER","GREEN")))) -> GREEN
A38: F-037 | B38: 3 | C38: Backend | D38: Respondent tokens, rate limits and consent | E38: Coding Plan Prompt 3.2. Hash-only tokens; generic 404; consent before first value. | F38: AI Assistant | G38: Critical | H38: Not Started | I38: 46307 | J38: 46309 | K38: 0 | L38: F-035 | M38: Run Prompt 3.2 | O38: =IF(H38="Done",0,IF(J38<TODAY(),"OVERDUE",J38-TODAY())) -> 24 | P38: =IF(H38="Blocked","RED",IF(H38="Done","GREEN",IF(J38<TODAY(),"RED",IF(J38-TODAY()<=7,"AMBER","GREEN")))) -> GREEN
A39: F-038 | B39: 3 | C39: Backend | D39: Upload request and presigned quarantine upload | E39: Coding Plan Prompt 3.3 (part 1). Size and type signed; 5-minute URL. | F39: AI Assistant | G39: Critical | H39: Not Started | I39: 46308 | J39: 46309 | K39: 0 | L39: F-037 | M39: Run Prompt 3.3 | O39: =IF(H39="Done",0,IF(J39<TODAY(),"OVERDUE",J39-TODAY())) -> 24 | P39: =IF(H39="Blocked","RED",IF(H39="Done","GREEN",IF(J39<TODAY(),"RED",IF(J39-TODAY()<=7,"AMBER","GREEN")))) -> GREEN
A40: F-039 | B40: 3 | C40: Security | D40: File-safety worker | E40: Coding Plan Prompt 3.3 (part 2). Sniff, ClamAV, PDF/image/archive limits, promote or quarantine, scan evidence. | F40: AI Assistant | G40: Critical | H40: Not Started | I40: 46309 | J40: 46310 | K40: 0 | L40: F-038 | M40: Run Prompt 3.3 | N40: Reviewer required | O40: =IF(H40="Done",0,IF(J40<TODAY(),"OVERDUE",J40-TODAY())) -> 25 | P40: =IF(H40="Blocked","RED",IF(H40="Done","GREEN",IF(J40<TODAY(),"RED",IF(J40-TODAY()<=7,"AMBER","GREEN")))) -> GREEN
...

Sheet Daily Status
A1: Date | B1: Day | C1: Overall Status | D1: % Project Complete | E1: Today’s Focus | F1: Completed Today | G1: Blockers / Risks | H1: Decision Needed | I1: Tomorrow’s Plan | J1: Owner | K1: Evidence / Link
A2: 46286 | B2: Monday | C2: Not Started | D2: 0 | J2: Founder
A3: 46287 | B3: Tuesday | C3: Not Started | D3: 0 | J3: Founder
A4: 46288 | B4: Wednesday | C4: Not Started | D4: 0 | J4: Founder
A5: 46289 | B5: Thursday | C5: Not Started | D5: 0 | J5: Founder
A6: 46290 | B6: Friday | C6: Not Started | D6: 0 | J6: Founder
A7: 46291 | B7: Saturday | C7: Not Started | D7: 0 | J7: Founder
A8: 46292 | B8: Sunday | C8: Not Started | D8: 0 | J8: Founder
A9: 46293 | B9: Monday | C9: Not Started | D9: 0 | J9: Founder
A10: 46294 | B10: Tuesday | C10: Not Started | D10: 0 | J10: Founder
A11: 46295 | B11: Wednesday | C11: Not Started | D11: 0 | J11: Founder
A12: 46296 | B12: Thursday | C12: Not Started | D12: 0 | J12: Founder
A13: 46297 | B13: Friday | C13: Not Started | D13: 0 | J13: Founder
... A104: 46388 | B104: Friday | C104: Not Started | D104: 0 | J104: Founder

Sheet Milestones
A1: Milestone | B1: Target Date | C1: Success Measure | D1: Status | E1: % Complete | F1: Owner | G1: Notes
A2: Discovery gate | B2: 46298 | C2: 8 of 15 interviews name the same problem; 3 firms committed to pilot | D2: Not Started | E2: 0 | F2: Founder | G2: Tasks F-001, F-002, F-008
A3: Tenant isolation gate | B3: 46304 | C3: Delivered 81 SQL checks and the API cross-tenant suite pass; reviewer sign-off | D3: Not Started | E3: 0 | F3: Founder | G3: Tasks F-029 to F-035
A4: Intake and file-safety gate | B4: 46311 | C4: Every hostile file quarantined; atomic submission; ID numbers ciphertext only | D4: Not Started | E4: 0 | F4: Founder | G4: Tasks F-036 to F-042
A5: Review and approval gate | B5: 46318 | C5: Reviewer resolves an exception; original AI result preserved; approval guard proven | D5: Not Started | E5: 0 | F5: Founder | G5: Tasks F-043 to F-046
A6: Reliability gate | B6: 46325 | C6: Zero silent loss and zero duplicate effects on 3 chaos runs | D6: Not Started | E6: 0 | F6: Founder | G6: Tasks F-047 to F-051
A7: AI benchmark gate | B7: 46332 | C7: p50, p95, peak memory, queue age, accuracy, calibration recorded against pre-registered thresholds | D7: Not Started | E7: 0 | F7: Founder | G7: Tasks F-052 to F-058
A8: POC decision | B8: 46353 | C8: Proceed / change approach / not sensitive-pilot ready, with evidence pack and restore proof | D8: Not Started | E8: 0 | F8: Founder | G8: Tasks F-059 to F-064
A9: Sensitive-pilot gate | B9: 46388 | C9: Tenant isolation, encrypted restore, rotation, alerts, retention, incident drill all evidenced | D9: Not Started | E9: 0 | F9: Founder | G9: Tasks F-065 to F-073
A10: Counsel review | B10: 46444 | C10: Processor terms, notice and consent, retention, breach process reviewed | D10: Not Started | E10: 0 | F10: Founder | G10: Tasks F-072, F-079
A11: Paid repeatability gate | B11: 46472 | C11: 3 paying logos and measured contribution margin | D11: Not Started | E11: 0 | F11: Founder | G11: Tasks F-074 to F-078
A12: DPDP commencement (watch date) | B12: 46520 | C12: Data Fiduciary obligations expected to commence; controls confirmed with counsel | D12: Not Started | E12: 0 | F12: Founder | G12: Task F-090
A13: Expansion decision | B13: 46538 | C13: Evidence-backed decision on next pack; 60% second-workflow demand and 70% reuse gates | D13: Not Started | E13: 0 | F13: Founder | G13: Tasks F-087 to F-089

Sheet Risks & Decisions
A1: ID | B1: Type | C1: Risk / Decision | D1: Impact | E1: Probability | F1: Mitigation / Next Step | G1: Owner | H1: Status | I1: Review Date
A2: R-001 | B2: Risk | C2: Oracle Always Free A1 allowance cut to 2 OCPU / 12 GB in total; Server #1 (4 OCPU / 24 GB) may be stopped or terminated; unpaid instances can be reclaimed | D2: High | E2: High | F2: Check console now; upgrade to Pay-As-You-Go; budget alert; treat VMs as disposable and backups as the asset. | G2: Founder | H2: Open | I2: 46290
A3: R-002 | B3: Risk | C3: CPU-only AI on VM2 too slow or inaccurate for onboarding documents | D3: High | E3: Medium | F3: Pre-registered benchmark; smallest passing model; bound concurrency; route to human review by default; no third VM. | G3: Founder | H3: Open | I3: 46332
A4: R-003 | B4: Risk | C4: AI classification or extraction error on sensitive documents | D4: High | E4: Medium | F4: Evidence-first output, grounding check, per-class calibration, human review, no autonomous sensitive actions, database approval guard. | G4: Founder | H4: Open | I4: 46315
A5: R-004 | B5: Risk | C5: Too many industries dilute product and sales focus | D5: High | E5: High | F5: Employee onboarding is the only launch wedge; paid-pilot and 70% reuse gates before any expansion. | G5: Founder | H5: Open | I5: 46290
A6: R-005 | B6: Risk | C6: Founder capacity is smaller than 12 phases of scope | D6: High | E6: High | F6: Build order 0-7, 10, pilots; phases 8 and 9 gated (ADR-05); slip rules cut SLA timers, delegation and analytics first; hire a technical reviewer. | G6: Founder | H6: Open | I6: 46304
A7: R-006 | B7: Risk | C7: AI-generated code contains subtle security defects | D7: High | E7: Medium | F7: CI gates, review checklist, generated IDOR suite, database as last line of defence, reviewer on phases 2, 3, 5, 6, 7, 10. | G7: Founder | H7: Open | I7: 46304
A8: R-007 | B8: Risk | C8: Server #1 compromised through SSH password login and NOPASSWD:ALL sudo user | D8: High | E8: Medium | F8: Task F-013: key-only SSH, no root login, least-privilege sudo, no public port 22, fail2ban, MFA on cloud accounts. | G8: Founder | H8: Open | I8: 46289
A9: R-008 | B9: Risk | C9: DPDP Data Fiduciary obligations expected from about 13 May 2027 while pilots run | D9: Medium | E9: High | F9: Consent and deletion built into schema; counsel engaged by February 2027; 72-hour breach process; processor terms. | G9: Founder | H9: Open | I9: 46444
A10: R-009 | B10: Risk | C10: Data-residency claim not supported: servers in India but R2 has no India-only location | D10: Medium | E10: Medium | F10: Do not claim India-only residency; decide document store (decision D-2) before first pilot. | G10: Founder | H10: Open | I10: 46296
A11: R-010 | B11: Risk | C11: Data loss because backups fail silently or restore has never been tested | D11: High | E11: Medium | F11: Nightly and 6-hourly encrypted backups, off-VM copy, backup-age alert, monthly restore drill as release gate. | G11: Founder | H11: Open | I11: 46339
A12: R-011 | B12: Risk | C12: Chosen model licence does not permit commercial use (licences differ by size within a family) | D12: High | E12: Medium | F12: Check and record licence in the registry before benchmarking; alternatives ready. | G12: Founder | H12: Open | I12: 46331
A13: R-012 | B13: Risk | C13: Provider terms or free-tier limits change (Vercel Hobby non-commercial, Clerk, Resend, R2, OCI) | D13: Medium | E13: Medium | F13: Vercel Pro; verify each provider at deployment and quarterly; cost model reviewed monthly. | G13: Founder | H13: Open | I13: 46297
... A34: D-019 | B34: Decision | C34: Open: independent penetration test (technical decision D-7) | D34: Medium | E34: Low | F34: Budget and provider. | G34: Founder | H34: Open | I34: 46370
